Workbook

Sheet Base_Data_Attrition_Assignment.
A1: Employee ID | B1: Business Unit | C1: Department | D1: Sub Department | E1: Reporting Director | F1: Location | G1: Work Mode (WFO/WFH) | H1: Date of Joining | I1: Date of Exit | J1: Employment Status | K1: Exit Type (Voluntary/Involuntary) | L1: Exit Reason Category | M1: Tenure in Days (as on 30-Jun-2026 / at exit)
A2: EMP1644 | B2: Exploring Infinities - Sales | C2: SALES | D2: Sales - English - India | E2: Director 2 | F2: Hyderabad | G2: WFH | H2: 46113 | I2: 46135 | J2: Relieved | K2: Voluntary | L2: Better Opportunity | M2: 22
A3: EMP1639 | B3: Exploring Infinities - Sales | C3: SALES | D3: Sales - English - India | E3: Director 2 | F3: Hyderabad | G3: WFH | H3: 45992 | I3: 46182 | J3: Relieved | K3: Involuntary | L3: Attendance / Discipline | M3: 190
A4: EMP1656 | B4: Exploring Infinities - Sales | C4: SALES | D4: Sales - English - India | E4: Director 2 | F4: Hyderabad | G4: WFH | H4: 46114 | J4: Active | M4: 89
A5: EMP1658 | B5: Exploring Infinities - Sales | C5: SALES | D5: Sales - English - India | E5: Director 2 | F5: Hyderabad | G5: WFH | H5: 46114 | J5: Active | M5: 89
A6: EMP1692 | B6: Exploring Infinities - Sales | C6: SALES | D6: Sales - English - India | E6: Director 2 | F6: Hyderabad | G6: WFH | H6: 46114 | I6: 46132 | J6: Relieved | K6: Voluntary | L6: Family Reasons | M6: 18
A7: EMP1693 | B7: Exploring Infinities - Sales | C7: SALES | D7: Sales - English - India | E7: Director 2 | F7: Hyderabad | G7: WFH | H7: 46114 | I7: 46161 | J7: Relieved | K7: Involuntary | L7: Attendance / Discipline | M7: 47
A8: EMP1694 | B8: Exploring Infinities - Sales | C8: SALES | D8: Sales - English - India | E8: Director 2 | F8: Hyderabad | G8: WFH | H8: 46114 | I8: 46121 | J8: Relieved | K8: Voluntary | L8: Relocation | M8: 7
A9: EMP1713 | B9: Exploring Infinities - Sales | C9: SALES | D9: Sales - English - India | E9: Director 2 | F9: Hyderabad | G9: WFH | H9: 46175 | J9: Active | M9: 28
A10: EMP1636 | B10: Exploring Infinities - Sales | C10: SALES | D10: Sales - English - India | E10: Director 2 | F10: Hyderabad | G10: WFH | H10: 45963 | J10: Active | M10: 240
A11: EMP1665 | B11: Exploring Infinities - Sales | C11: SALES | D11: Sales - English - India | E11: Director 2 | F11: Hyderabad | G11: WFH | H11: 46115 | I11: 46134 | J11: Relieved | K11: Voluntary | L11: Higher Studies | M11: 19
A12: EMP1711 | B12: Exploring Infinities - Sales | C12: SALES | D12: Sales - English - India | E12: Director 2 | F12: Hyderabad | G12: WFH | H12: 46176 | I12: 46195 | J12: Relieved | K12: Voluntary | L12: Family Reasons | M12: 19
A13: EMP1646 | B13: Exploring Infinities - Sales | C13: SALES | D13: Sales - English - India | E13: Director 2 | F13: Hyderabad | G13: WFH | H13: 46116 | I13: 46166 | J13: Relieved | K13: Involuntary | L13: Attendance / Discipline | M13: 50
A14: EMP1676 | B14: Exploring Infinities - Sales | C14: SALES | D14: Sales - English - India | E14: Director 2 | F14: Hyderabad | G14: WFH | H14: 46116 | I14: 46144 | J14: Relieved | K14: Involuntary | L14: Role Redundancy | M14: 28
A15: EMP1678 | B15: Exploring Infinities - Sales | C15: SALES | D15: Sales - English - India | E15: Director 2 | F15: Hyderabad | G15: WFH | H15: 46116 | I15: 46131 | J15: Relieved | K15: Voluntary | L15: Higher Studies | M15: 15
A16: EMP1628 | B16: Exploring Infinities - Sales | C16: SALES | D16: Sales - English - India | E16: Director 2 | F16: Hyderabad | G16: WFH | H16: 45781 | I16: 46164 | J16: Relieved | K16: Involuntary | L16: Policy Violation | M16: 383
A17: EMP1648 | B17: Exploring Infinities - Sales | C17: SALES | D17: Sales - English - India | E17: Director 2 | F17: Hyderabad | G17: WFH | H17: 46117 | J17: Active | M17: 86
A18: EMP1677 | B18: Exploring Infinities - Sales | C18: SALES | D18: Sales - English - India | E18: Director 2 | F18: Hyderabad | G18: WFH | H18: 46117 | I18: 46126 | J18: Relieved | K18: Voluntary | L18: Family Reasons | M18: 9
A19: EMP1686 | B19: Exploring Infinities - Sales | C19: SALES | D19: Sales - English - India | E19: Director 2 | F19: Hyderabad | G19: WFH | H19: 46117 | J19: Active | M19: 86
A20: EMP1695 | B20: Exploring Infinities - Sales | C20: SALES | D20: Sales - English - India | E20: Director 2 | F20: Hyderabad | G20: WFH | H20: 46117 | I20: 46133 | J20: Relieved | K20: Voluntary | L20: Better Opportunity | M20: 16
A21: EMP1702 | B21: Exploring Infinities - Sales | C21: SALES | D21: Sales - English - India | E21: Director 2 | F21: Hyderabad | G21: WFH | H21: 46117 | I21: 46120 | J21: Relieved | K21: Voluntary | L21: Personal Reasons | M21: 3
A22: EMP1706 | B22: Exploring Infinities - Sales | C22: SALES | D22: Sales - English - India | E22: Director 2 | F22: Hyderabad | G22: WFH | H22: 46117 | I22: 46120 | J22: Relieved | K22: Voluntary | L22: Family Reasons | M22: 3
A23: EMP1611 | B23: Exploring Infinities - Sales | C23: SALES | D23: Sales - English - India | E23: Director 2 | F23: Hyderabad | G23: WFH | H23: 46027 | I23: 46167 | J23: Relieved | K23: Involuntary | L23: Attendance / Discipline | M23: 140
A24: EMP1661 | B24: Exploring Infinities - Sales | C24: SALES | D24: Sales - English - India | E24: Director 2 | F24: Hyderabad | G24: WFH | H24: 46119 | J24: Active | M24: 84
A25: EMP1687 | B25: Exploring Infinities - Sales | C25: SALES | D25: Sales - English - India | E25: Director 2 | F25: Hyderabad | G25: WFH | H25: 46119 | I25: 46166 | J25: Relieved | K25: Involuntary | L25: Performance Related | M25: 47
A26: EMP1621 | B26: Exploring Infinities - Sales | C26: SALES | D26: Sales - English - India | E26: Director 2 | F26: Hyderabad | G26: WFH | H26: 45815 | I26: 46122 | J26: Relieved | K26: Involuntary | L26: Role Redundancy | M26: 307
A27: EMP1613 | B27: Exploring Infinities - Sales | C27: SALES | D27: Sales - English - India | E27: Director 2 | F27: Hyderabad | G27: WFH | H27: 45755 | I27: 46119 | J27: Relieved | K27: Voluntary | L27: Better Opportunity | M27: 364
A28: EMP1638 | B28: Exploring Infinities - Sales | C28: SALES | D28: Sales - English - India | E28: Director 2 | F28: Hyderabad | G28: WFH | H28: 46089 | I28: 46131 | J28: Relieved | K28: Involuntary | L28: Performance Related | M28: 42
A29: EMP1650 | B29: Exploring Infinities - Sales | C29: SALES | D29: Sales - English - India | E29: Director 2 | F29: Hyderabad | G29: WFH | H29: 46121 | I29: 46157 | J29: Relieved | K29: Voluntary | L29: Family Reasons | M29: 36
A30: EMP1671 | B30: Exploring Infinities - Sales | C30: SALES | D30: Sales - English - India | E30: Director 2 | F30: Hyderabad | G30: WFH | H30: 46121 | I30: 46124 | J30: Relieved | K30: Voluntary | L30: Health Reasons | M30: 3
A31: EMP1664 | B31: Exploring Infinities - Sales | C31: SALES | D31: Sales - English - India | E31: Director 2 | F31: Hyderabad | G31: WFH | H31: 46122 | I31: 46148 | J31: Relieved | K31: Involuntary | L31: Policy Violation | M31: 26
A32: EMP1612 | B32: Exploring Infinities - Sales | C32: SALES | D32: Sales - English - India | E32: Director 2 | F32: Hyderabad | G32: WFH | H32: 45818 | I32: 46144 | J32: Relieved | K32: Involuntary | L32: Attendance / Discipline | M32: 326
A33: EMP1682 | B33: Exploring Infinities - Sales | C33: SALES | D33: Sales - English - India | E33: Director 2 | F33: Hyderabad | G33: WFH | H33: 46123 | I33: 46165 | J33: Relieved | K33: Involuntary | L33: Role Redundancy | M33: 42
A34: EMP1697 | B34: Exploring Infinities - Sales | C34: SALES | D34: Sales - English - India | E34: Director 2 | F34: Hyderabad | G34: WFH | H34: 46123 | I34: 46123 | J34: Relieved | K34: Voluntary | L34: Personal Reasons | M34: 0
A35: EMP1640 | B35: Exploring Infinities - Sales | C35: SALES | D35: Sales - English - India | E35: Director 2 | F35: Hyderabad | G35: WFH | H35: 46002 | I35: 46142 | J35: Relieved | K35: Involuntary | L35: Policy Violation | M35: 140
A36: EMP1635 | B36: Exploring Infinities - Sales | C36: SALES | D36: Sales - English - India | E36: Director 2 | F36: Hyderabad | G36: WFH | H36: 45911 | I36: 46133 | J36: Relieved | K36: Involuntary | L36: Attendance / Discipline | M36: 222
A37: EMP1652 | B37: Exploring Infinities - Sales | C37: SALES | D37: Sales - English - India | E37: Director 2 | F37: Hyderabad | G37: WFH | H37: 46124 | J37: Active | M37: 79
A38: EMP1655 | B38: Exploring Infinities - Sales | C38: SALES | D38: Sales - English - India | E38: Director 2 | F38: Hyderabad | G38: WFH | H38: 46124 | I38: 46173 | J38: Relieved | K38: Voluntary | L38: Higher Studies | M38: 49
A39: EMP1662 | B39: Exploring Infinities - Sales | C39: SALES | D39: Sales - English - India | E39: Director 2 | F39: Hyderabad | G39: WFH | H39: 46124 | I39: 46164 | J39: Relieved | K39: Involuntary | L39: Performance Related | M39: 40
A40: EMP1680 | B40: Exploring Infinities - Sales | C40: SALES | D40: Sales - English - India | E40: Director 2 | F40: Hyderabad | G40: WFH | H40: 46124 | J40: Active | M40: 79
...

Sheet Work_data
A1: Employee ID | B1: Business Unit | C1: Department | D1: Sub Department | E1: Reporting Director | F1: Location | G1: Work Mode (WFO/WFH) | H1: Date of Joining | I1: Date of Exit | J1: Employment Status | K1: Exit Type (Voluntary/Involuntary) | L1: Exit Reason Category | M1: Tenure in Days (as on 30-Jun-2026 / at exit) | N1: Exit _status | O1: Join_month | P1: exit_month | Q1: Voluntary_exit | R1: Involuntary_exit | S1: Tenure Bucket
A2: EMP1644 | B2: Exploring Infinities - Sales | C2: SALES | D2: Sales - English - India | E2: Director 2 | F2: Hyderabad | G2: WFH | H2: 46113 | I2: 46135 | J2: Relieved | K2: Voluntary | L2: Better Opportunity | M2: 22 | N2: =IF(J2="Relieved",1,0) -> 1 | O2: =TEXT(H2,"mm-yyyy") -> 04-2026 | P2: =IF(I2="","",TEXT(I2,"mm-yyyy")) -> 04-2026 | Q2: =IF(K2="Voluntary",1,0) -> 1 | R2: =IF(K2="Involuntary",1,0) -> 0 | S2: =IF(M2<90,"0-90",IF(M2<180,"90-180",IF(M2<365,"180-365","above 1 year"))) -> 0-90
A3: EMP1639 | B3: Exploring Infinities - Sales | C3: SALES | D3: Sales - English - India | E3: Director 2 | F3: Hyderabad | G3: WFH | H3: 45992 | I3: 46182 | J3: Relieved | K3: Involuntary | L3: Attendance / Discipline | M3: 190 | N3: =IF(J3="Relieved",1,0) -> 1 | O3: =TEXT(H3,"mm-yyyy") -> 12-2025 | P3: =IF(I3="","",TEXT(I3,"mm-yyyy")) -> 06-2026 | Q3: =IF(K3="Voluntary",1,0) -> 0 | R3: =IF(K3="Involuntary",1,0) -> 1 | S3: =IF(M3<90,"0-90",IF(M3<180,"90-180",IF(M3<365,"180-365","above 1 year"))) -> 180-365
A4: EMP1656 | B4: Exploring Infinities - Sales | C4: SALES | D4: Sales - English - India | E4: Director 2 | F4: Hyderabad | G4: WFH | H4: 46114 | J4: Active | M4: 89 | N4: =IF(J4="Relieved",1,0) -> 0 | O4: =TEXT(H4,"mm-yyyy") -> 04-2026 | P4: =IF(I4="","",TEXT(I4,"mm-yyyy")) | Q4: =IF(K4="Voluntary",1,0) -> 0 | R4: =IF(K4="Involuntary",1,0) -> 0 | S4: =IF(M4<90,"0-90",IF(M4<180,"90-180",IF(M4<365,"180-365","above 1 year"))) -> 0-90
A5: EMP1658 | B5: Exploring Infinities - Sales | C5: SALES | D5: Sales - English - India | E5: Director 2 | F5: Hyderabad | G5: WFH | H5: 46114 | J5: Active | M5: 89 | N5: =IF(J5="Relieved",1,0) -> 0 | O5: =TEXT(H5,"mm-yyyy") -> 04-2026 | P5: =IF(I5="","",TEXT(I5,"mm-yyyy")) | Q5: =IF(K5="Voluntary",1,0) -> 0 | R5: =IF(K5="Involuntary",1,0) -> 0 | S5: =IF(M5<90,"0-90",IF(M5<180,"90-180",IF(M5<365,"180-365","above 1 year"))) -> 0-90
A6: EMP1692 | B6: Exploring Infinities - Sales | C6: SALES | D6: Sales - English - India | E6: Director 2 | F6: Hyderabad | G6: WFH | H6: 46114 | I6: 46132 | J6: Relieved | K6: Voluntary | L6: Family Reasons | M6: 18 | N6: =IF(J6="Relieved",1,0) -> 1 | O6: =TEXT(H6,"mm-yyyy") -> 04-2026 | P6: =IF(I6="","",TEXT(I6,"mm-yyyy")) -> 04-2026 | Q6: =IF(K6="Voluntary",1,0) -> 1 | R6: =IF(K6="Involuntary",1,0) -> 0 | S6: =IF(M6<90,"0-90",IF(M6<180,"90-180",IF(M6<365,"180-365","above 1 year"))) -> 0-90
A7: EMP1693 | B7: Exploring Infinities - Sales | C7: SALES | D7: Sales - English - India | E7: Director 2 | F7: Hyderabad | G7: WFH | H7: 46114 | I7: 46161 | J7: Relieved | K7: Involuntary | L7: Attendance / Discipline | M7: 47 | N7: =IF(J7="Relieved",1,0) -> 1 | O7: =TEXT(H7,"mm-yyyy") -> 04-2026 | P7: =IF(I7="","",TEXT(I7,"mm-yyyy")) -> 05-2026 | Q7: =IF(K7="Voluntary",1,0) -> 0 | R7: =IF(K7="Involuntary",1,0) -> 1 | S7: =IF(M7<90,"0-90",IF(M7<180,"90-180",IF(M7<365,"180-365","above 1 year"))) -> 0-90
A8: EMP1694 | B8: Exploring Infinities - Sales | C8: SALES | D8: Sales - English - India | E8: Director 2 | F8: Hyderabad | G8: WFH | H8: 46114 | I8: 46121 | J8: Relieved | K8: Voluntary | L8: Relocation | M8: 7 | N8: =IF(J8="Relieved",1,0) -> 1 | O8: =TEXT(H8,"mm-yyyy") -> 04-2026 | P8: =IF(I8="","",TEXT(I8,"mm-yyyy")) -> 04-2026 | Q8: =IF(K8="Voluntary",1,0) -> 1 | R8: =IF(K8="Involuntary",1,0) -> 0 | S8: =IF(M8<90,"0-90",IF(M8<180,"90-180",IF(M8<365,"180-365","above 1 year"))) -> 0-90
A9: EMP1713 | B9: Exploring Infinities - Sales | C9: SALES | D9: Sales - English - India | E9: Director 2 | F9: Hyderabad | G9: WFH | H9: 46175 | J9: Active | M9: 28 | N9: =IF(J9="Relieved",1,0) -> 0 | O9: =TEXT(H9,"mm-yyyy") -> 06-2026 | P9: =IF(I9="","",TEXT(I9,"mm-yyyy")) | Q9: =IF(K9="Voluntary",1,0) -> 0 | R9: =IF(K9="Involuntary",1,0) -> 0 | S9: =IF(M9<90,"0-90",IF(M9<180,"90-180",IF(M9<365,"180-365","above 1 year"))) -> 0-90
A10: EMP1636 | B10: Exploring Infinities - Sales | C10: SALES | D10: Sales - English - India | E10: Director 2 | F10: Hyderabad | G10: WFH | H10: 45963 | J10: Active | M10: 240 | N10: =IF(J10="Relieved",1,0) -> 0 | O10: =TEXT(H10,"mm-yyyy") -> 11-2025 | P10: =IF(I10="","",TEXT(I10,"mm-yyyy")) | Q10: =IF(K10="Voluntary",1,0) -> 0 | R10: =IF(K10="Involuntary",1,0) -> 0 | S10: =IF(M10<90,"0-90",IF(M10<180,"90-180",IF(M10<365,"180-365","above 1 year"))) -> 180-365
A11: EMP1665 | B11: Exploring Infinities - Sales | C11: SALES | D11: Sales - English - India | E11: Director 2 | F11: Hyderabad | G11: WFH | H11: 46115 | I11: 46134 | J11: Relieved | K11: Voluntary | L11: Higher Studies | M11: 19 | N11: =IF(J11="Relieved",1,0) -> 1 | O11: =TEXT(H11,"mm-yyyy") -> 04-2026 | P11: =IF(I11="","",TEXT(I11,"mm-yyyy")) -> 04-2026 | Q11: =IF(K11="Voluntary",1,0) -> 1 | R11: =IF(K11="Involuntary",1,0) -> 0 | S11: =IF(M11<90,"0-90",IF(M11<180,"90-180",IF(M11<365,"180-365","above 1 year"))) -> 0-90
A12: EMP1711 | B12: Exploring Infinities - Sales | C12: SALES | D12: Sales - English - India | E12: Director 2 | F12: Hyderabad | G12: WFH | H12: 46176 | I12: 46195 | J12: Relieved | K12: Voluntary | L12: Family Reasons | M12: 19 | N12: =IF(J12="Relieved",1,0) -> 1 | O12: =TEXT(H12,"mm-yyyy") -> 06-2026 | P12: =IF(I12="","",TEXT(I12,"mm-yyyy")) -> 06-2026 | Q12: =IF(K12="Voluntary",1,0) -> 1 | R12: =IF(K12="Involuntary",1,0) -> 0 | S12: =IF(M12<90,"0-90",IF(M12<180,"90-180",IF(M12<365,"180-365","above 1 year"))) -> 0-90
A13: EMP1646 | B13: Exploring Infinities - Sales | C13: SALES | D13: Sales - English - India | E13: Director 2 | F13: Hyderabad | G13: WFH | H13: 46116 | I13: 46166 | J13: Relieved | K13: Involuntary | L13: Attendance / Discipline | M13: 50 | N13: =IF(J13="Relieved",1,0) -> 1 | O13: =TEXT(H13,"mm-yyyy") -> 04-2026 | P13: =IF(I13="","",TEXT(I13,"mm-yyyy")) -> 05-2026 | Q13: =IF(K13="Voluntary",1,0) -> 0 | R13: =IF(K13="Involuntary",1,0) -> 1 | S13: =IF(M13<90,"0-90",IF(M13<180,"90-180",IF(M13<365,"180-365","above 1 year"))) -> 0-90
A14: EMP1676 | B14: Exploring Infinities - Sales | C14: SALES | D14: Sales - English - India | E14: Director 2 | F14: Hyderabad | G14: WFH | H14: 46116 | I14: 46144 | J14: Relieved | K14: Involuntary | L14: Role Redundancy | M14: 28 | N14: =IF(J14="Relieved",1,0) -> 1 | O14: =TEXT(H14,"mm-yyyy") -> 04-2026 | P14: =IF(I14="","",TEXT(I14,"mm-yyyy")) -> 05-2026 | Q14: =IF(K14="Voluntary",1,0) -> 0 | R14: =IF(K14="Involuntary",1,0) -> 1 | S14: =IF(M14<90,"0-90",IF(M14<180,"90-180",IF(M14<365,"180-365","above 1 year"))) -> 0-90
A15: EMP1678 | B15: Exploring Infinities - Sales | C15: SALES | D15: Sales - English - India | E15: Director 2 | F15: Hyderabad | G15: WFH | H15: 46116 | I15: 46131 | J15: Relieved | K15: Voluntary | L15: Higher Studies | M15: 15 | N15: =IF(J15="Relieved",1,0) -> 1 | O15: =TEXT(H15,"mm-yyyy") -> 04-2026 | P15: =IF(I15="","",TEXT(I15,"mm-yyyy")) -> 04-2026 | Q15: =IF(K15="Voluntary",1,0) -> 1 | R15: =IF(K15="Involuntary",1,0) -> 0 | S15: =IF(M15<90,"0-90",IF(M15<180,"90-180",IF(M15<365,"180-365","above 1 year"))) -> 0-90
A16: EMP1628 | B16: Exploring Infinities - Sales | C16: SALES | D16: Sales - English - India | E16: Director 2 | F16: Hyderabad | G16: WFH | H16: 45781 | I16: 46164 | J16: Relieved | K16: Involuntary | L16: Policy Violation | M16: 383 | N16: =IF(J16="Relieved",1,0) -> 1 | O16: =TEXT(H16,"mm-yyyy") -> 05-2025 | P16: =IF(I16="","",TEXT(I16,"mm-yyyy")) -> 05-2026 | Q16: =IF(K16="Voluntary",1,0) -> 0 | R16: =IF(K16="Involuntary",1,0) -> 1 | S16: =IF(M16<90,"0-90",IF(M16<180,"90-180",IF(M16<365,"180-365","above 1 year"))) -> above 1 year
A17: EMP1648 | B17: Exploring Infinities - Sales | C17: SALES | D17: Sales - English - India | E17: Director 2 | F17: Hyderabad | G17: WFH | H17: 46117 | J17: Active | M17: 86 | N17: =IF(J17="Relieved",1,0) -> 0 | O17: =TEXT(H17,"mm-yyyy") -> 04-2026 | P17: =IF(I17="","",TEXT(I17,"mm-yyyy")) | Q17: =IF(K17="Voluntary",1,0) -> 0 | R17: =IF(K17="Involuntary",1,0) -> 0 | S17: =IF(M17<90,"0-90",IF(M17<180,"90-180",IF(M17<365,"180-365","above 1 year"))) -> 0-90
A18: EMP1677 | B18: Exploring Infinities - Sales | C18: SALES | D18: Sales - English - India | E18: Director 2 | F18: Hyderabad | G18: WFH | H18: 46117 | I18: 46126 | J18: Relieved | K18: Voluntary | L18: Family Reasons | M18: 9 | N18: =IF(J18="Relieved",1,0) -> 1 | O18: =TEXT(H18,"mm-yyyy") -> 04-2026 | P18: =IF(I18="","",TEXT(I18,"mm-yyyy")) -> 04-2026 | Q18: =IF(K18="Voluntary",1,0) -> 1 | R18: =IF(K18="Involuntary",1,0) -> 0 | S18: =IF(M18<90,"0-90",IF(M18<180,"90-180",IF(M18<365,"180-365","above 1 year"))) -> 0-90
A19: EMP1686 | B19: Exploring Infinities - Sales | C19: SALES | D19: Sales - English - India | E19: Director 2 | F19: Hyderabad | G19: WFH | H19: 46117 | J19: Active | M19: 86 | N19: =IF(J19="Relieved",1,0) -> 0 | O19: =TEXT(H19,"mm-yyyy") -> 04-2026 | P19: =IF(I19="","",TEXT(I19,"mm-yyyy")) | Q19: =IF(K19="Voluntary",1,0) -> 0 | R19: =IF(K19="Involuntary",1,0) -> 0 | S19: =IF(M19<90,"0-90",IF(M19<180,"90-180",IF(M19<365,"180-365","above 1 year"))) -> 0-90
A20: EMP1695 | B20: Exploring Infinities - Sales | C20: SALES | D20: Sales - English - India | E20: Director 2 | F20: Hyderabad | G20: WFH | H20: 46117 | I20: 46133 | J20: Relieved | K20: Voluntary | L20: Better Opportunity | M20: 16 | N20: =IF(J20="Relieved",1,0) -> 1 | O20: =TEXT(H20,"mm-yyyy") -> 04-2026 | P20: =IF(I20="","",TEXT(I20,"mm-yyyy")) -> 04-2026 | Q20: =IF(K20="Voluntary",1,0) -> 1 | R20: =IF(K20="Involuntary",1,0) -> 0 | S20: =IF(M20<90,"0-90",IF(M20<180,"90-180",IF(M20<365,"180-365","above 1 year"))) -> 0-90
A21: EMP1702 | B21: Exploring Infinities - Sales | C21: SALES | D21: Sales - English - India | E21: Director 2 | F21: Hyderabad | G21: WFH | H21: 46117 | I21: 46120 | J21: Relieved | K21: Voluntary | L21: Personal Reasons | M21: 3 | N21: =IF(J21="Relieved",1,0) -> 1 | O21: =TEXT(H21,"mm-yyyy") -> 04-2026 | P21: =IF(I21="","",TEXT(I21,"mm-yyyy")) -> 04-2026 | Q21: =IF(K21="Voluntary",1,0) -> 1 | R21: =IF(K21="Involuntary",1,0) -> 0 | S21: =IF(M21<90,"0-90",IF(M21<180,"90-180",IF(M21<365,"180-365","above 1 year"))) -> 0-90
A22: EMP1706 | B22: Exploring Infinities - Sales | C22: SALES | D22: Sales - English - India | E22: Director 2 | F22: Hyderabad | G22: WFH | H22: 46117 | I22: 46120 | J22: Relieved | K22: Voluntary | L22: Family Reasons | M22: 3 | N22: =IF(J22="Relieved",1,0) -> 1 | O22: =TEXT(H22,"mm-yyyy") -> 04-2026 | P22: =IF(I22="","",TEXT(I22,"mm-yyyy")) -> 04-2026 | Q22: =IF(K22="Voluntary",1,0) -> 1 | R22: =IF(K22="Involuntary",1,0) -> 0 | S22: =IF(M22<90,"0-90",IF(M22<180,"90-180",IF(M22<365,"180-365","above 1 year"))) -> 0-90
A23: EMP1611 | B23: Exploring Infinities - Sales | C23: SALES | D23: Sales - English - India | E23: Director 2 | F23: Hyderabad | G23: WFH | H23: 46027 | I23: 46167 | J23: Relieved | K23: Involuntary | L23: Attendance / Discipline | M23: 140 | N23: =IF(J23="Relieved",1,0) -> 1 | O23: =TEXT(H23,"mm-yyyy") -> 01-2026 | P23: =IF(I23="","",TEXT(I23,"mm-yyyy")) -> 05-2026 | Q23: =IF(K23="Voluntary",1,0) -> 0 | R23: =IF(K23="Involuntary",1,0) -> 1 | S23: =IF(M23<90,"0-90",IF(M23<180,"90-180",IF(M23<365,"180-365","above 1 year"))) -> 90-180
A24: EMP1661 | B24: Exploring Infinities - Sales | C24: SALES | D24: Sales - English - India | E24: Director 2 | F24: Hyderabad | G24: WFH | H24: 46119 | J24: Active | M24: 84 | N24: =IF(J24="Relieved",1,0) -> 0 | O24: =TEXT(H24,"mm-yyyy") -> 04-2026 | P24: =IF(I24="","",TEXT(I24,"mm-yyyy")) | Q24: =IF(K24="Voluntary",1,0) -> 0 | R24: =IF(K24="Involuntary",1,0) -> 0 | S24: =IF(M24<90,"0-90",IF(M24<180,"90-180",IF(M24<365,"180-365","above 1 year"))) -> 0-90
A25: EMP1687 | B25: Exploring Infinities - Sales | C25: SALES | D25: Sales - English - India | E25: Director 2 | F25: Hyderabad | G25: WFH | H25: 46119 | I25: 46166 | J25: Relieved | K25: Involuntary | L25: Performance Related | M25: 47 | N25: =IF(J25="Relieved",1,0) -> 1 | O25: =TEXT(H25,"mm-yyyy") -> 04-2026 | P25: =IF(I25="","",TEXT(I25,"mm-yyyy")) -> 05-2026 | Q25: =IF(K25="Voluntary",1,0) -> 0 | R25: =IF(K25="Involuntary",1,0) -> 1 | S25: =IF(M25<90,"0-90",IF(M25<180,"90-180",IF(M25<365,"180-365","above 1 year"))) -> 0-90
A26: EMP1621 | B26: Exploring Infinities - Sales | C26: SALES | D26: Sales - English - India | E26: Director 2 | F26: Hyderabad | G26: WFH | H26: 45815 | I26: 46122 | J26: Relieved | K26: Involuntary | L26: Role Redundancy | M26: 307 | N26: =IF(J26="Relieved",1,0) -> 1 | O26: =TEXT(H26,"mm-yyyy") -> 06-2025 | P26: =IF(I26="","",TEXT(I26,"mm-yyyy")) -> 04-2026 | Q26: =IF(K26="Voluntary",1,0) -> 0 | R26: =IF(K26="Involuntary",1,0) -> 1 | S26: =IF(M26<90,"0-90",IF(M26<180,"90-180",IF(M26<365,"180-365","above 1 year"))) -> 180-365
A27: EMP1613 | B27: Exploring Infinities - Sales | C27: SALES | D27: Sales - English - India | E27: Director 2 | F27: Hyderabad | G27: WFH | H27: 45755 | I27: 46119 | J27: Relieved | K27: Voluntary | L27: Better Opportunity | M27: 364 | N27: =IF(J27="Relieved",1,0) -> 1 | O27: =TEXT(H27,"mm-yyyy") -> 04-2025 | P27: =IF(I27="","",TEXT(I27,"mm-yyyy")) -> 04-2026 | Q27: =IF(K27="Voluntary",1,0) -> 1 | R27: =IF(K27="Involuntary",1,0) -> 0 | S27: =IF(M27<90,"0-90",IF(M27<180,"90-180",IF(M27<365,"180-365","above 1 year"))) -> 180-365
A28: EMP1638 | B28: Exploring Infinities - Sales | C28: SALES | D28: Sales - English - India | E28: Director 2 | F28: Hyderabad | G28: WFH | H28: 46089 | I28: 46131 | J28: Relieved | K28: Involuntary | L28: Performance Related | M28: 42 | N28: =IF(J28="Relieved",1,0) -> 1 | O28: =TEXT(H28,"mm-yyyy") -> 03-2026 | P28: =IF(I28="","",TEXT(I28,"mm-yyyy")) -> 04-2026 | Q28: =IF(K28="Voluntary",1,0) -> 0 | R28: =IF(K28="Involuntary",1,0) -> 1 | S28: =IF(M28<90,"0-90",IF(M28<180,"90-180",IF(M28<365,"180-365","above 1 year"))) -> 0-90
A29: EMP1650 | B29: Exploring Infinities - Sales | C29: SALES | D29: Sales - English - India | E29: Director 2 | F29: Hyderabad | G29: WFH | H29: 46121 | I29: 46157 | J29: Relieved | K29: Voluntary | L29: Family Reasons | M29: 36 | N29: =IF(J29="Relieved",1,0) -> 1 | O29: =TEXT(H29,"mm-yyyy") -> 04-2026 | P29: =IF(I29="","",TEXT(I29,"mm-yyyy")) -> 05-2026 | Q29: =IF(K29="Voluntary",1,0) -> 1 | R29: =IF(K29="Involuntary",1,0) -> 0 | S29: =IF(M29<90,"0-90",IF(M29<180,"90-180",IF(M29<365,"180-365","above 1 year"))) -> 0-90
A30: EMP1671 | B30: Exploring Infinities - Sales | C30: SALES | D30: Sales - English - India | E30: Director 2 | F30: Hyderabad | G30: WFH | H30: 46121 | I30: 46124 | J30: Relieved | K30: Voluntary | L30: Health Reasons | M30: 3 | N30: =IF(J30="Relieved",1,0) -> 1 | O30: =TEXT(H30,"mm-yyyy") -> 04-2026 | P30: =IF(I30="","",TEXT(I30,"mm-yyyy")) -> 04-2026 | Q30: =IF(K30="Voluntary",1,0) -> 1 | R30: =IF(K30="Involuntary",1,0) -> 0 | S30: =IF(M30<90,"0-90",IF(M30<180,"90-180",IF(M30<365,"180-365","above 1 year"))) -> 0-90
A31: EMP1664 | B31: Exploring Infinities - Sales | C31: SALES | D31: Sales - English - India | E31: Director 2 | F31: Hyderabad | G31: WFH | H31: 46122 | I31: 46148 | J31: Relieved | K31: Involuntary | L31: Policy Violation | M31: 26 | N31: =IF(J31="Relieved",1,0) -> 1 | O31: =TEXT(H31,"mm-yyyy") -> 04-2026 | P31: =IF(I31="","",TEXT(I31,"mm-yyyy")) -> 05-2026 | Q31: =IF(K31="Voluntary",1,0) -> 0 | R31: =IF(K31="Involuntary",1,0) -> 1 | S31: =IF(M31<90,"0-90",IF(M31<180,"90-180",IF(M31<365,"180-365","above 1 year"))) -> 0-90
A32: EMP1612 | B32: Exploring Infinities - Sales | C32: SALES | D32: Sales - English - India | E32: Director 2 | F32: Hyderabad | G32: WFH | H32: 45818 | I32: 46144 | J32: Relieved | K32: Involuntary | L32: Attendance / Discipline | M32: 326 | N32: =IF(J32="Relieved",1,0) -> 1 | O32: =TEXT(H32,"mm-yyyy") -> 06-2025 | P32: =IF(I32="","",TEXT(I32,"mm-yyyy")) -> 05-2026 | Q32: =IF(K32="Voluntary",1,0) -> 0 | R32: =IF(K32="Involuntary",1,0) -> 1 | S32: =IF(M32<90,"0-90",IF(M32<180,"90-180",IF(M32<365,"180-365","above 1 year"))) -> 180-365
A33: EMP1682 | B33: Exploring Infinities - Sales | C33: SALES | D33: Sales - English - India | E33: Director 2 | F33: Hyderabad | G33: WFH | H33: 46123 | I33: 46165 | J33: Relieved | K33: Involuntary | L33: Role Redundancy | M33: 42 | N33: =IF(J33="Relieved",1,0) -> 1 | O33: =TEXT(H33,"mm-yyyy") -> 04-2026 | P33: =IF(I33="","",TEXT(I33,"mm-yyyy")) -> 05-2026 | Q33: =IF(K33="Voluntary",1,0) -> 0 | R33: =IF(K33="Involuntary",1,0) -> 1 | S33: =IF(M33<90,"0-90",IF(M33<180,"90-180",IF(M33<365,"180-365","above 1 year"))) -> 0-90
A34: EMP1697 | B34: Exploring Infinities - Sales | C34: SALES | D34: Sales - English - India | E34: Director 2 | F34: Hyderabad | G34: WFH | H34: 46123 | I34: 46123 | J34: Relieved | K34: Voluntary | L34: Personal Reasons | M34: 0 | N34: =IF(J34="Relieved",1,0) -> 1 | O34: =TEXT(H34,"mm-yyyy") -> 04-2026 | P34: =IF(I34="","",TEXT(I34,"mm-yyyy")) -> 04-2026 | Q34: =IF(K34="Voluntary",1,0) -> 1 | R34: =IF(K34="Involuntary",1,0) -> 0 | S34: =IF(M34<90,"0-90",IF(M34<180,"90-180",IF(M34<365,"180-365","above 1 year"))) -> 0-90
A35: EMP1640 | B35: Exploring Infinities - Sales | C35: SALES | D35: Sales - English - India | E35: Director 2 | F35: Hyderabad | G35: WFH | H35: 46002 | I35: 46142 | J35: Relieved | K35: Involuntary | L35: Policy Violation | M35: 140 | N35: =IF(J35="Relieved",1,0) -> 1 | O35: =TEXT(H35,"mm-yyyy") -> 12-2025 | P35: =IF(I35="","",TEXT(I35,"mm-yyyy")) -> 04-2026 | Q35: =IF(K35="Voluntary",1,0) -> 0 | R35: =IF(K35="Involuntary",1,0) -> 1 | S35: =IF(M35<90,"0-90",IF(M35<180,"90-180",IF(M35<365,"180-365","above 1 year"))) -> 90-180
A36: EMP1635 | B36: Exploring Infinities - Sales | C36: SALES | D36: Sales - English - India | E36: Director 2 | F36: Hyderabad | G36: WFH | H36: 45911 | I36: 46133 | J36: Relieved | K36: Involuntary | L36: Attendance / Discipline | M36: 222 | N36: =IF(J36="Relieved",1,0) -> 1 | O36: =TEXT(H36,"mm-yyyy") -> 09-2025 | P36: =IF(I36="","",TEXT(I36,"mm-yyyy")) -> 04-2026 | Q36: =IF(K36="Voluntary",1,0) -> 0 | R36: =IF(K36="Involuntary",1,0) -> 1 | S36: =IF(M36<90,"0-90",IF(M36<180,"90-180",IF(M36<365,"180-365","above 1 year"))) -> 180-365
A37: EMP1652 | B37: Exploring Infinities - Sales | C37: SALES | D37: Sales - English - India | E37: Director 2 | F37: Hyderabad | G37: WFH | H37: 46124 | J37: Active | M37: 79 | N37: =IF(J37="Relieved",1,0) -> 0 | O37: =TEXT(H37,"mm-yyyy") -> 04-2026 | P37: =IF(I37="","",TEXT(I37,"mm-yyyy")) | Q37: =IF(K37="Voluntary",1,0) -> 0 | R37: =IF(K37="Involuntary",1,0) -> 0 | S37: =IF(M37<90,"0-90",IF(M37<180,"90-180",IF(M37<365,"180-365","above 1 year"))) -> 0-90
A38: EMP1655 | B38: Exploring Infinities - Sales | C38: SALES | D38: Sales - English - India | E38: Director 2 | F38: Hyderabad | G38: WFH | H38: 46124 | I38: 46173 | J38: Relieved | K38: Voluntary | L38: Higher Studies | M38: 49 | N38: =IF(J38="Relieved",1,0) -> 1 | O38: =TEXT(H38,"mm-yyyy") -> 04-2026 | P38: =IF(I38="","",TEXT(I38,"mm-yyyy")) -> 05-2026 | Q38: =IF(K38="Voluntary",1,0) -> 1 | R38: =IF(K38="Involuntary",1,0) -> 0 | S38: =IF(M38<90,"0-90",IF(M38<180,"90-180",IF(M38<365,"180-365","above 1 year"))) -> 0-90
A39: EMP1662 | B39: Exploring Infinities - Sales | C39: SALES | D39: Sales - English - India | E39: Director 2 | F39: Hyderabad | G39: WFH | H39: 46124 | I39: 46164 | J39: Relieved | K39: Involuntary | L39: Performance Related | M39: 40 | N39: =IF(J39="Relieved",1,0) -> 1 | O39: =TEXT(H39,"mm-yyyy") -> 04-2026 | P39: =IF(I39="","",TEXT(I39,"mm-yyyy")) -> 05-2026 | Q39: =IF(K39="Voluntary",1,0) -> 0 | R39: =IF(K39="Involuntary",1,0) -> 1 | S39: =IF(M39<90,"0-90",IF(M39<180,"90-180",IF(M39<365,"180-365","above 1 year"))) -> 0-90
A40: EMP1680 | B40: Exploring Infinities - Sales | C40: SALES | D40: Sales - English - India | E40: Director 2 | F40: Hyderabad | G40: WFH | H40: 46124 | J40: Active | M40: 79 | N40: =IF(J40="Relieved",1,0) -> 0 | O40: =TEXT(H40,"mm-yyyy") -> 04-2026 | P40: =IF(I40="","",TEXT(I40,"mm-yyyy")) | Q40: =IF(K40="Voluntary",1,0) -> 0 | R40: =IF(K40="Involuntary",1,0) -> 0 | S40: =IF(M40<90,"0-90",IF(M40<180,"90-180",IF(M40<365,"180-365","above 1 year"))) -> 0-90
...

Sheet Sheet3
A1: Actions taken:
A2: Added Helper columns
A3: changed data type to short date for "Date of joining" and "Date of exit" columns

Sheet Dashboard
E2: Emplpyee Attrition Dashboard
E3: April - June 2026 || | G3: MIS Analysis
B5: Opening Headcount | D5: Closing Headcount | F5: Average Headcount | H5: June's Attrition %
B6: ='Monthly Summary table'!B3 -> 335 | D6: ='Monthly Summary table'!D4 -> 332 | F6: =AVERAGE('Monthly Summary table'!B5:D5) -> 373.16667 | I6: ='Monthly Summary table'!D8 -> 0.53276353

Sheet Monthly Summary table
A1: Monthly Summary Table | L1: Voluntary attrition % | M1: Involuntary attrition %
A2: Metric | B2: 46113 | C2: 46143 | D2: 46174 | K2: 46113 | L2: =B11 -> 0.26754967 | M2: =B12 -> 0.2013245
A3: Opening Headcount | B3: =COUNTIFS(Work_data!H:H,"<="&DATE(2026,4,1),Work_data!I:I,">="&DATE(2026,4,1))+COUNTIFS(Work_data!H:H,"<="&DATE(2026,4,1),Work_data!I:I,"") -> 335 | C3: =COUNTIFS(Work_data!H:H,"<="&DATE(2026,5,1),Work_data!I:I,">="&DATE(2026,5,1))+COUNTIFS(Work_data!H:H,"<="&DATE(2026,5,1),Work_data!I:I,"") -> 409 | D3: =COUNTIFS(Work_data!H:H,"<="&DATE(2026,6,1),Work_data!I:I,">="&DATE(2026,6,1))+COUNTIFS(Work_data!H:H,"<="&DATE(2026,6,1),Work_data!I:I,"") -> 370 | K3: 46143 | L3: =C11 -> 0.24040921 | M3: =C12 -> 0.29411765
A4: Closing Headcount | B4: =COUNTIFS(Work_data!H:H,"<="&DATE(2026,4,30),Work_data!I:I,">="&DATE(2026,4,30))+COUNTIFS(Work_data!H:H,"<="&DATE(2026,4,30),Work_data!I:I,"") -> 420 | C4: =COUNTIFS(Work_data!H:H,"<="&DATE(2026,5,31),Work_data!I:I,">="&DATE(2026,5,31))+COUNTIFS(Work_data!H:H,"<="&DATE(2026,5,31),Work_data!I:I,"") -> 373 | D4: =COUNTIFS(Work_data!H:H,"<="&DATE(2026,6,30),Work_data!I:I,">="&DATE(2026,6,30))+COUNTIFS(Work_data!H:H,"<="&DATE(2026,6,31),Work_data!I:I,"") -> 332 | K4: 46174 | L4: =D11 -> 0.27065527 | M4: =D12 -> 0.26210826
A5: Average Headcount | B5: =(B3+B4)/2 -> 377.5 | C5: =(C3+C4)/2 -> 391 | D5: =(D3+D4)/2 -> 351
A6: Joiners | B6: =COUNTIFS(Work_data!H:H,">="&DATE(2026,4,1),Work_data!H:H,"<="&DATE(2026,4,30)) -> 257 | C6: =COUNTIFS(Work_data!H:H,">="&DATE(2026,5,1),Work_data!H:H,"<="&DATE(2026,5,31)) -> 166 | D6: =COUNTIFS(Work_data!H:H,">="&DATE(2026,6,1),Work_data!H:H,"<="&DATE(2026,6,30)) -> 148
A7: Exits | B7: =COUNTIFS(Work_data!I:I,">="&DATE(2026,4,1),Work_data!I:I,"<="&DATE(2026,4,30)) -> 177 | C7: =COUNTIFS(Work_data!I:I,">="&DATE(2026,5,1),Work_data!I:I,"<="&DATE(2026,5,31)) -> 209 | D7: =COUNTIFS(Work_data!I:I,">="&DATE(2026,6,1),Work_data!I:I,"<="&DATE(2026,6,30)) -> 187
A8: Attrition % | B8: =B7/B5 -> 0.46887417 | C8: =C7/C5 -> 0.53452685 | D8: =D7/D5 -> 0.53276353
A9: Voluntary exits | B9: =COUNTIFS(Work_data!I:I,">="&DATE(2026,4,1),Work_data!I:I,"<="&DATE(2026,4,30),Work_data!K:K,"Voluntary") -> 101 | C9: =COUNTIFS(Work_data!I:I,">="&DATE(2026,5,1),Work_data!I:I,"<="&DATE(2026,5,31),Work_data!K:K,"Voluntary") -> 94 | D9: =COUNTIFS(Work_data!I:I,">="&DATE(2026,6,1),Work_data!I:I,"<="&DATE(2026,6,30),Work_data!K:K,"Voluntary") -> 95
A10: Involuntary exits | B10: =COUNTIFS(Work_data!I:I,">="&DATE(2026,4,1),Work_data!I:I,"<="&DATE(2026,4,30),Work_data!K:K,"Involuntary") -> 76 | C10: =COUNTIFS(Work_data!I:I,">="&DATE(2026,5,1),Work_data!I:I,"<="&DATE(2026,5,31),Work_data!K:K,"Involuntary") -> 115 | D10: =COUNTIFS(Work_data!I:I,">="&DATE(2026,6,1),Work_data!I:I,"<="&DATE(2026,6,30),Work_data!K:K,"Involuntary") -> 92
A11: Voluntary attrition % | B11: =B9/B5 -> 0.26754967 | C11: =C9/C5 -> 0.24040921 | D11: =D9/D5 -> 0.27065527
A12: Involuntary attrition % | B12: =B10/B5 -> 0.2013245 | C12: =C10/C5 -> 0.29411765 | D12: =D10/D5 -> 0.26210826

Sheet Sub-departments
A1: Sub-Departments : | B1: 46113 | C1: 46143 | D1: 46174
A2: Sales - English - India | B2: 0.52849741 | C2: 0.73493976 | D2: 0.2745098
A3: Sales - India | B3: 0.46075949 | C3: 0.50900901 | D3: 0.61503417
A4: Sales - ROW - ANZ | B4: 0.4 | C4: 0.42666667 | D4: 0.35820896
A5: Sales - ROW - GCC | B5: 0.43478261 | C5: 0.39175258 | D5: 0.55319149

Sheet Sales - English - India
A1: Analysis for -- | B1: Sales - English - India
A3: Monthly Summary Table
A4: Metric | B4: 46113 | C4: 46143 | D4: 46174
A5: Opening Headcount | B5: =COUNTIFS(Work_data!D:D,'Sales - English - India'!B1,Work_data!H:H,"<="&DATE(2026,4,1),Work_data!I:I,">="&DATE(2026,4,1))+COUNTIFS(Work_data!D:D,'Sales - English - India'!B1,Work_data!H:H,"<="&DATE(2026,4,1),Work_data!I:I,"") -> 76 | C5: =COUNTIFS(Work_data!D:D,'Sales - English - India'!B1,Work_data!H:H,"<="&DATE(2026,5,1),Work_data!I:I,">="&DATE(2026,5,1))+COUNTIFS(Work_data!D:D,'Sales - English - India'!B1,Work_data!H:H,"<="&DATE(2026,5,1),Work_data!I:I,"") -> 110 | D5: =COUNTIFS(Work_data!D:D,'Sales - English - India'!B1,Work_data!H:H,"<="&DATE(2026,6,1),Work_data!I:I,">="&DATE(2026,6,1))+COUNTIFS(Work_data!D:D,'Sales - English - India'!B1,Work_data!H:H,"<="&DATE(2026,6,1),Work_data!I:I,"") -> 53
A6: Closing Headcount | B6: =COUNTIFS(Work_data!D:D,'Sales - English - India'!B1,Work_data!H:H,"<="&DATE(2026,4,30),Work_data!I:I,">="&DATE(2026,4,30))+COUNTIFS(Work_data!D:D,'Sales - English - India'!B1,Work_data!H:H,"<="&DATE(2026,4,30),Work_data!I:I,"") -> 117 | C6: =COUNTIFS(Work_data!D:D,'Sales - English - India'!B1,Work_data!H:H,"<="&DATE(2026,5,31),Work_data!I:I,">="&DATE(2026,5,31))+COUNTIFS(Work_data!D:D,'Sales - English - India'!B1,Work_data!H:H,"<="&DATE(2026,5,31),Work_data!I:I,"") -> 56 | D6: =COUNTIFS(Work_data!D:D,'Sales - English - India'!B1,Work_data!H:H,"<="&DATE(2026,6,30),Work_data!I:I,">="&DATE(2026,6,30))+COUNTIFS(Work_data!D:D,'Sales - English - India'!B1,Work_data!H:H,"<="&DATE(2026,6,30),Work_data!I:I,"") -> 49
A7: Average Headcount | B7: =(B5+B6)/2 -> 96.5 | C7: =(C5+C6)/2 -> 83 | D7: =(D5+D6)/2 -> 51
A8: Joiners | B8: =COUNTIFS(Work_data!D:D,'Sales - English - India'!B1,Work_data!H:H,">="&DATE(2026,4,1),Work_data!H:H,"<="&DATE(2026,4,30)) -> 86 | C8: =COUNTIFS(Work_data!D:D,'Sales - English - India'!B1,Work_data!H:H,">="&DATE(2026,5,1),Work_data!H:H,"<="&DATE(2026,5,31)) -> 4 | D8: =COUNTIFS(Work_data!D:D,'Sales - English - India'!B1,Work_data!H:H,">="&DATE(2026,6,1),Work_data!H:H,"<="&DATE(2026,6,30)) -> 8
A9: Exits | B9: =COUNTIFS(Work_data!D:D,'Sales - English - India'!B1,Work_data!I:I,">="&DATE(2026,4,1),Work_data!I:I,"<="&DATE(2026,4,30)) -> 51 | C9: =COUNTIFS(Work_data!D:D,'Sales - English - India'!B1,Work_data!I:I,">="&DATE(2026,5,1),Work_data!I:I,"<="&DATE(2026,5,31)) -> 61 | D9: =COUNTIFS(Work_data!D:D,'Sales - English - India'!B1,Work_data!I:I,">="&DATE(2026,6,1),Work_data!I:I,"<="&DATE(2026,6,30)) -> 14
A10: Attrition % | B10: =B9/B7 -> 0.52849741 | C10: =C9/C7 -> 0.73493976 | D10: =D9/D7 -> 0.2745098
A11: Voluntary exits | B11: =COUNTIFS(Work_data!D:D,'Sales - English - India'!B1,Work_data!I:I,">="&DATE(2026,4,1),Work_data!I:I,"<="&DATE(2026,4,30),Work_data!K:K,"Voluntary") -> 33 | C11: =COUNTIFS(Work_data!D:D,'Sales - English - India'!B1,Work_data!I:I,">="&DATE(2026,5,1),Work_data!I:I,"<="&DATE(2026,5,31),Work_data!K:K,"Voluntary") -> 14 | D11: =COUNTIFS(Work_data!D:D,'Sales - English - India'!B1,Work_data!I:I,">="&DATE(2026,6,1),Work_data!I:I,"<="&DATE(2026,6,30),Work_data!K:K,"Voluntary") -> 7
A12: Involuntary exits | B12: =COUNTIFS(Work_data!D:D,'Sales - English - India'!B1,Work_data!I:I,">="&DATE(2026,4,1),Work_data!I:I,"<="&DATE(2026,4,30),Work_data!K:K,"Involuntary") -> 18 | C12: =COUNTIFS(Work_data!D:D,'Sales - English - India'!B1,Work_data!I:I,">="&DATE(2026,5,1),Work_data!I:I,"<="&DATE(2026,5,31),Work_data!K:K,"Involuntary") -> 47 | D12: =COUNTIFS(Work_data!D:D,'Sales - English - India'!B1,Work_data!I:I,">="&DATE(2026,6,1),Work_data!I:I,"<="&DATE(2026,6,30),Work_data!K:K,"Involuntary") -> 7
A13: Voluntary attrition % | B13: =B11/B7 -> 0.34196891 | C13: =C11/C7 -> 0.1686747 | D13: =D12/D7 -> 0.1372549
A14: Involuntary attrition % | B14: =B12/B7 -> 0.1865285 | C14: =C12/C7 -> 0.56626506 | D14: =D12/D7 -> 0.1372549

Sheet Sales - India
A1: Analysis for -- | B1: Sales - India
A3: Monthly Summary Table
A4: Metric | B4: 46113 | C4: 46143 | D4: 46174
A5: Opening Headcount | B5: =COUNTIFS(Work_data!D:D,'Sales - India'!B1,Work_data!H:H,"<="&DATE(2026,4,1),Work_data!I:I,">="&DATE(2026,4,1))+COUNTIFS(Work_data!D:D,'Sales - India'!B1,Work_data!H:H,"<="&DATE(2026,4,1),Work_data!I:I,"") -> 183 | C5: =COUNTIFS(Work_data!D:D,'Sales - India'!B1,Work_data!H:H,"<="&DATE(2026,5,1),Work_data!I:I,">="&DATE(2026,5,1))+COUNTIFS(Work_data!D:D,'Sales - India'!B1,Work_data!H:H,"<="&DATE(2026,5,1),Work_data!I:I,"") -> 210 | D5: =COUNTIFS(Work_data!D:D,'Sales - India'!B1,Work_data!H:H,"<="&DATE(2026,6,1),Work_data!I:I,">="&DATE(2026,6,1))+COUNTIFS(Work_data!D:D,'Sales - India'!B1,Work_data!H:H,"<="&DATE(2026,6,1),Work_data!I:I,"") -> 233
A6: Closing Headcount | B6: =COUNTIFS(Work_data!D:D,'Sales - India'!B1,Work_data!H:H,"<="&DATE(2026,4,30),Work_data!I:I,">="&DATE(2026,4,30))+COUNTIFS(Work_data!D:D,'Sales - India'!B1,Work_data!H:H,"<="&DATE(2026,4,30),Work_data!I:I,"") -> 212 | C6: =COUNTIFS(Work_data!D:D,'Sales - India'!B1,Work_data!H:H,"<="&DATE(2026,5,31),Work_data!I:I,">="&DATE(2026,5,31))+COUNTIFS(Work_data!D:D,'Sales - India'!B1,Work_data!H:H,"<="&DATE(2026,5,31),Work_data!I:I,"") -> 234 | D6: =COUNTIFS(Work_data!D:D,'Sales - India'!B1,Work_data!H:H,"<="&DATE(2026,6,30),Work_data!I:I,">="&DATE(2026,6,30))+COUNTIFS(Work_data!D:D,'Sales - India'!B1,Work_data!H:H,"<="&DATE(2026,6,30),Work_data!I:I,"") -> 206
A7: Average Headcount | B7: =(B5+B6)/2 -> 197.5 | C7: =(C5+C6)/2 -> 222 | D7: =(D5+D6)/2 -> 219.5
A8: Joiners | B8: =COUNTIFS(Work_data!D:D,'Sales - India'!B1,Work_data!H:H,">="&DATE(2026,4,1),Work_data!H:H,"<="&DATE(2026,4,30)) -> 122 | C8: =COUNTIFS(Work_data!D:D,'Sales - India'!B1,Work_data!H:H,">="&DATE(2026,5,1),Work_data!H:H,"<="&DATE(2026,5,31)) -> 134 | D8: =COUNTIFS(Work_data!D:D,'Sales - India'!B1,Work_data!H:H,">="&DATE(2026,6,1),Work_data!H:H,"<="&DATE(2026,6,31)) -> 110
A9: Exits | B9: =COUNTIFS(Work_data!D:D,'Sales - India'!B1,Work_data!I:I,">="&DATE(2026,4,1),Work_data!I:I,"<="&DATE(2026,4,30)) -> 91 | C9: =COUNTIFS(Work_data!D:D,'Sales - India'!B1,Work_data!I:I,">="&DATE(2026,5,1),Work_data!I:I,"<="&DATE(2026,5,31)) -> 113 | D9: =COUNTIFS(Work_data!D:D,'Sales - India'!B1,Work_data!I:I,">="&DATE(2026,6,1),Work_data!I:I,"<="&DATE(2026,6,30)) -> 135
A10: Attrition % | B10: =B9/B7 -> 0.46075949 | C10: =C9/C7 -> 0.50900901 | D10: =D9/D7 -> 0.61503417
A11: Voluntary exits | B11: =COUNTIFS(Work_data!D:D,'Sales - India'!B1,Work_data!I:I,">="&DATE(2026,4,1),Work_data!I:I,"<="&DATE(2026,4,30),Work_data!K:K,"Voluntary") -> 54 | C11: =COUNTIFS(Work_data!D:D,'Sales - India'!B1,Work_data!I:I,">="&DATE(2026,5,1),Work_data!I:I,"<="&DATE(2026,5,31),Work_data!K:K,"Voluntary") -> 55 | D11: =COUNTIFS(Work_data!D:D,'Sales - India'!B1,Work_data!I:I,">="&DATE(2026,6,1),Work_data!I:I,"<="&DATE(2026,6,30),Work_data!K:K,"Voluntary") -> 71
A12: Involuntary exits | B12: =COUNTIFS(Work_data!D:D,'Sales - India'!B1,Work_data!I:I,">="&DATE(2026,4,1),Work_data!I:I,"<="&DATE(2026,4,30),Work_data!K:K,"Involuntary") -> 37 | C12: =COUNTIFS(Work_data!D:D,'Sales - India'!B1,Work_data!I:I,">="&DATE(2026,5,1),Work_data!I:I,"<="&DATE(2026,5,31),Work_data!K:K,"Involuntary") -> 58 | D12: =COUNTIFS(Work_data!D:D,'Sales - India'!B1,Work_data!I:I,">="&DATE(2026,6,1),Work_data!I:I,"<="&DATE(2026,6,30),Work_data!K:K,"Involuntary") -> 64
A13: Voluntary attrition % | B13: =B11/B7 -> 0.27341772 | C13: =C11/C7 -> 0.24774775 | D13: =D11/D7 -> 0.32346241
A14: Involuntary attrition % | B14: =B12/B7 -> 0.18734177 | C14: =C12/C7 -> 0.26126126 | D14: =D12/D7 -> 0.29157175

Sheet Sales - ROW - GCC
A1: Analysis for -- | B1: Sales - ROW - GCC
A3: Monthly Summary Table
A4: Metric | B4: 46113 | C4: 46143 | D4: 46174
A5: Opening Headcount | B5: =COUNTIFS(Work_data!D:D,B1,Work_data!H:H,"<="&DATE(2026,4,1),Work_data!I:I,">="&DATE(2026,4,1))+COUNTIFS(Work_data!D:D,B1,Work_data!H:H,"<="&DATE(2026,4,1),Work_data!I:I,"") -> 43 | C5: =COUNTIFS(Work_data!D:D,B1,Work_data!H:H,"<="&DATE(2026,5,1),Work_data!I:I,">="&DATE(2026,5,1))+COUNTIFS(Work_data!D:D,B1,Work_data!H:H,"<="&DATE(2026,5,1),Work_data!I:I,"") -> 48 | D5: =COUNTIFS(Work_data!D:D,B1,Work_data!H:H,"<="&DATE(2026,6,1),Work_data!I:I,">="&DATE(2026,6,1))+COUNTIFS(Work_data!D:D,B1,Work_data!H:H,"<="&DATE(2026,6,1),Work_data!I:I,"") -> 50
A6: Closing Headcount | B6: =COUNTIFS(Work_data!D:D,B1,Work_data!H:H,"<="&DATE(2026,4,30),Work_data!I:I,">="&DATE(2026,4,30))+COUNTIFS(Work_data!D:D,B1,Work_data!H:H,"<="&DATE(2026,4,30),Work_data!I:I,"") -> 49 | C6: =COUNTIFS(Work_data!D:D,B1,Work_data!H:H,"<="&DATE(2026,5,31),Work_data!I:I,">="&DATE(2026,5,31))+COUNTIFS(Work_data!D:D,B1,Work_data!H:H,"<="&DATE(2026,5,31),Work_data!I:I,"") -> 49 | D6: =COUNTIFS(Work_data!D:D,B1,Work_data!H:H,"<="&DATE(2026,6,30),Work_data!I:I,">="&DATE(2026,6,30))+COUNTIFS(Work_data!D:D,B1,Work_data!H:H,"<="&DATE(2026,6,30),Work_data!I:I,"") -> 44
A7: Average Headcount | B7: =(B5+B6)/2 -> 46 | C7: =(C5+C6)/2 -> 48.5 | D7: =(D5+D6)/2 -> 47
A8: Joiners | B8: =COUNTIFS(Work_data!D:D,'Sales - ROW - GCC'!B1,Work_data!H:H,">="&DATE(2026,4,1),Work_data!H:H,"<="&DATE(2026,4,30)) -> 26 | C8: =COUNTIFS(Work_data!D:D,'Sales - ROW - GCC'!B1,Work_data!H:H,">="&DATE(2026,5,1),Work_data!H:H,"<="&DATE(2026,5,31)) -> 19 | D8: =COUNTIFS(Work_data!D:D,'Sales - ROW - GCC'!B1,Work_data!H:H,">="&DATE(2026,6,1),Work_data!H:H,"<="&DATE(2026,6,30)) -> 22
A9: Exits | B9: =COUNTIFS(Work_data!D:D,'Sales - ROW - GCC'!B1,Work_data!I:I,">="&DATE(2026,4,1),Work_data!I:I,"<="&DATE(2026,4,30)) -> 20 | C9: =COUNTIFS(Work_data!D:D,'Sales - ROW - GCC'!B1,Work_data!I:I,">="&DATE(2026,5,1),Work_data!I:I,"<="&DATE(2026,5,31)) -> 19 | D9: =COUNTIFS(Work_data!D:D,'Sales - ROW - GCC'!B1,Work_data!I:I,">="&DATE(2026,6,1),Work_data!I:I,"<="&DATE(2026,6,30)) -> 26
A10: Attrition % | B10: =B9/B7 -> 0.43478261 | C10: =C9/C7 -> 0.39175258 | D10: =D9/D7 -> 0.55319149
A11: Voluntary exits | B11: =COUNTIFS(Work_data!D:D,'Sales - ROW - GCC'!B1,Work_data!I:I,">="&DATE(2026,4,1),Work_data!I:I,"<="&DATE(2026,4,30),Work_data!K:K,"Voluntary") -> 9 | C11: =COUNTIFS(Work_data!D:D,'Sales - ROW - GCC'!B1,Work_data!I:I,">="&DATE(2026,5,1),Work_data!I:I,"<="&DATE(2026,5,31),Work_data!K:K,"Voluntary") -> 13 | D11: =COUNTIFS(Work_data!D:D,'Sales - ROW - GCC'!B1,Work_data!I:I,">="&DATE(2026,6,1),Work_data!I:I,"<="&DATE(2026,6,30),Work_data!K:K,"Voluntary") -> 14
A12: Involuntary exits | B12: =COUNTIFS(Work_data!D:D,'Sales - ROW - GCC'!B1,Work_data!I:I,">="&DATE(2026,4,1),Work_data!I:I,"<="&DATE(2026,4,30),Work_data!K:K,"Involuntary") -> 11 | C12: =COUNTIFS(Work_data!D:D,'Sales - ROW - GCC'!B1,Work_data!I:I,">="&DATE(2026,5,1),Work_data!I:I,"<="&DATE(2026,5,31),Work_data!K:K,"Involuntary") -> 6 | D12: =COUNTIFS(Work_data!D:D,'Sales - ROW - GCC'!B1,Work_data!I:I,">="&DATE(2026,6,1),Work_data!I:I,"<="&DATE(2026,6,30),Work_data!K:K,"Involuntary") -> 12
A13: Voluntary attrition % | B13: =B11/B7 -> 0.19565217 | C13: =C11/C7 -> 0.26804124 | D13: =D11/D7 -> 0.29787234
A14: Involuntary attrition % | B14: =B12/B7 -> 0.23913043 | C14: =C12/C7 -> 0.12371134 | D14: =D12/D7 -> 0.25531915

Sheet Sales - ROW - ANZ
A1: Analysis for -- | B1: Sales - ROW - ANZ
A3: Monthly Summary Table
A4: Metric | B4: 46113 | C4: 46143 | D4: 46174
A5: Opening Headcount | B5: =COUNTIFS(Work_data!D:D,'Sales - ROW - ANZ'!B1,Work_data!H:H,"<="&DATE(2026,4,1),Work_data!I:I,">="&DATE(2026,4,1))+COUNTIFS(Work_data!D:D,'Sales - ROW - ANZ'!B1,Work_data!H:H,"<="&DATE(2026,4,1),Work_data!I:I,"") -> 33 | C5: =COUNTIFS(Work_data!D:D,'Sales - ROW - ANZ'!B1,Work_data!H:H,"<="&DATE(2026,5,1),Work_data!I:I,">="&DATE(2026,5,1))+COUNTIFS(Work_data!D:D,'Sales - ROW - ANZ'!B1,Work_data!H:H,"<="&DATE(2026,5,1),Work_data!I:I,"") -> 41 | D5: =COUNTIFS(Work_data!D:D,'Sales - ROW - ANZ'!B1,Work_data!H:H,"<="&DATE(2026,6,1),Work_data!I:I,">="&DATE(2026,6,1))+COUNTIFS(Work_data!D:D,'Sales - ROW - ANZ'!B1,Work_data!H:H,"<="&DATE(2026,6,1),Work_data!I:I,"") -> 34
A6: Closing Headcount | B6: =COUNTIFS(Work_data!D:D,'Sales - ROW - ANZ'!B1,Work_data!H:H,"<="&DATE(2026,4,30),Work_data!I:I,">="&DATE(2026,4,30))+COUNTIFS(Work_data!D:D,'Sales - ROW - ANZ'!B1,Work_data!H:H,"<="&DATE(2026,4,30),Work_data!I:I,"") -> 42 | C6: =COUNTIFS(Work_data!D:D,'Sales - ROW - ANZ'!B1,Work_data!H:H,"<="&DATE(2026,5,31),Work_data!I:I,">="&DATE(2026,5,31))+COUNTIFS(Work_data!D:D,'Sales - ROW - ANZ'!B1,Work_data!H:H,"<="&DATE(2026,5,31),Work_data!I:I,"") -> 34 | D6: =COUNTIFS(Work_data!D:D,'Sales - ROW - ANZ'!B1,Work_data!H:H,"<="&DATE(2026,6,30),Work_data!I:I,">="&DATE(2026,6,30))+COUNTIFS(Work_data!D:D,'Sales - ROW - ANZ'!B1,Work_data!H:H,"<="&DATE(2026,6,30),Work_data!I:I,"") -> 33
A7: Average Headcount | B7: =(B5+B6)/2 -> 37.5 | C7: =(C5+C6)/2 -> 37.5 | D7: =(D5+D6)/2 -> 33.5
A8: Joiners | B8: =COUNTIFS(Work_data!D:D,'Sales - ROW - ANZ'!B1,Work_data!H:H,">="&DATE(2026,4,1),Work_data!H:H,"<="&DATE(2026,4,30)) -> 23 | C8: =COUNTIFS(Work_data!D:D,'Sales - ROW - ANZ'!B1,Work_data!H:H,">="&DATE(2026,5,1),Work_data!H:H,"<="&DATE(2026,5,31)) -> 9 | D8: =COUNTIFS(Work_data!D:D,'Sales - ROW - ANZ'!B1,Work_data!H:H,">="&DATE(2026,6,1),Work_data!H:H,"<="&DATE(2026,6,30)) -> 8
A9: Exits | B9: =COUNTIFS(Work_data!D:D,'Sales - ROW - ANZ'!B1,Work_data!I:I,">="&DATE(2026,4,1),Work_data!I:I,"<="&DATE(2026,4,30)) -> 15 | C9: =COUNTIFS(Work_data!D:D,'Sales - ROW - ANZ'!B1,Work_data!I:I,">="&DATE(2026,5,1),Work_data!I:I,"<="&DATE(2026,5,31)) -> 16 | D9: =COUNTIFS(Work_data!D:D,'Sales - ROW - ANZ'!B1,Work_data!I:I,">="&DATE(2026,6,1),Work_data!I:I,"<="&DATE(2026,6,30)) -> 12
A10: Attrition % | B10: =B9/B7 -> 0.4 | C10: =C9/C7 -> 0.42666667 | D10: =D9/D7 -> 0.35820896
A11: Voluntary exits | B11: =COUNTIFS(Work_data!D:D,'Sales - ROW - ANZ'!B1,Work_data!I:I,">="&DATE(2026,4,1),Work_data!I:I,"<="&DATE(2026,4,30),Work_data!K:K,"Voluntary") -> 5 | C11: =COUNTIFS(Work_data!D:D,'Sales - ROW - ANZ'!B1,Work_data!I:I,">="&DATE(2026,5,1),Work_data!I:I,"<="&DATE(2026,5,31),Work_data!K:K,"Voluntary") -> 12 | D11: =COUNTIFS(Work_data!D:D,'Sales - ROW - ANZ'!B1,Work_data!I:I,">="&DATE(2026,6,1),Work_data!I:I,"<="&DATE(2026,6,31),Work_data!K:K,"Voluntary") -> 3
A12: Involuntary exits | B12: =COUNTIFS(Work_data!D:D,'Sales - ROW - ANZ'!B1,Work_data!I:I,">="&DATE(2026,4,1),Work_data!I:I,"<="&DATE(2026,4,30),Work_data!K:K,"Involuntary") -> 10 | C12: =COUNTIFS(Work_data!D:D,'Sales - ROW - ANZ'!B1,Work_data!I:I,">="&DATE(2026,5,1),Work_data!I:I,"<="&DATE(2026,5,31),Work_data!K:K,"Involuntary") -> 4 | D12: =COUNTIFS(Work_data!D:D,'Sales - ROW - ANZ'!B1,Work_data!I:I,">="&DATE(2026,6,1),Work_data!I:I,"<="&DATE(2026,6,31),Work_data!K:K,"Involuntary") -> 9
A13: Voluntary attrition % | B13: =B11/B7 -> 0.13333333 | C13: =C11/C7 -> 0.32 | D13: =D11/D7 -> 0.089552239
A14: Involuntary attrition % | B14: =B12/B7 -> 0.26666667 | C14: =C12/C7 -> 0.10666667 | D14: =D12/D7 -> 0.26865672

Sheet WFH Analysis
A1: Analysis by Work-Mode | C1: WFH
A3: Metric | B3: 46113 | C3: 46143 | D3: 46174
A4: Opening Headcount | B4: =COUNTIFS(Work_data!G:G,'WFH Analysis'!C1,Work_data!H:H,"<="&DATE(2026,4,1),Work_data!I:I,">="&DATE(2026,4,1))+COUNTIFS(Work_data!G:G,"WFH",Work_data!H:H,"<="&DATE(2026,4,1),Work_data!I:I,"") -> 221 | C4: =COUNTIFS(Work_data!G:G,'WFH Analysis'!C1,Work_data!H:H,"<="&DATE(2026,5,1),Work_data!I:I,">="&DATE(2026,5,1))+COUNTIFS(Work_data!G:G,"WFH",Work_data!H:H,"<="&DATE(2026,5,1),Work_data!I:I,"") -> 286 | D4: =COUNTIFS(Work_data!G:G,'WFH Analysis'!C1,Work_data!H:H,"<="&DATE(2026,6,1),Work_data!I:I,">="&DATE(2026,6,1))+COUNTIFS(Work_data!G:G,"WFH",Work_data!H:H,"<="&DATE(2026,6,1),Work_data!I:I,"") -> 274
A5: Closing Headcount | B5: =COUNTIFS(Work_data!G:G,'WFH Analysis'!C1,Work_data!H:H,"<="&DATE(2026,4,30),Work_data!I:I,">="&DATE(2026,4,30))+COUNTIFS(Work_data!G:G,'WFH Analysis'!C1,Work_data!H:H,"<="&DATE(2026,4,30),Work_data!I:I,"") -> 295 | C5: =COUNTIFS(Work_data!G:G,'WFH Analysis'!C1,Work_data!H:H,"<="&DATE(2026,5,31),Work_data!I:I,">="&DATE(2026,5,31))+COUNTIFS(Work_data!G:G,'WFH Analysis'!C1,Work_data!H:H,"<="&DATE(2026,5,31),Work_data!I:I,"") -> 275 | D5: =COUNTIFS(Work_data!G:G,'WFH Analysis'!C1,Work_data!H:H,"<="&DATE(2026,6,30),Work_data!I:I,">="&DATE(2026,6,30))+COUNTIFS(Work_data!G:G,'WFH Analysis'!C1,Work_data!H:H,"<="&DATE(2026,6,30),Work_data!I:I,"") -> 237
A6: Average Headcount | B6: =(B4+B5)/2 -> 258 | C6: =(C4+C5)/2 -> 280.5 | D6: =(D4+D5)/2 -> 255.5
A7: Joiners | B7: =COUNTIFS(Work_data!G:G,'WFH Analysis'!C1,Work_data!H:H,">="&DATE(2026,4,1),Work_data!H:H,"<="&DATE(2026,4,30)) -> 211 | C7: =COUNTIFS(Work_data!G:G,'WFH Analysis'!C1,Work_data!H:H,">="&DATE(2026,5,1),Work_data!H:H,"<="&DATE(2026,5,31)) -> 134 | D7: =COUNTIFS(Work_data!G:G,'WFH Analysis'!C1,Work_data!H:H,">="&DATE(2026,6,1),Work_data!H:H,"<="&DATE(2026,6,30)) -> 121
A8: Exits | B8: =COUNTIFS(Work_data!G:G,'WFH Analysis'!C1,Work_data!I:I,">="&DATE(2026,4,1),Work_data!I:I,"<="&DATE(2026,4,30)) -> 140 | C8: =COUNTIFS(Work_data!G:G,'WFH Analysis'!C1,Work_data!I:I,">="&DATE(2026,5,1),Work_data!I:I,"<="&DATE(2026,5,31)) -> 149 | D8: =COUNTIFS(Work_data!G:G,'WFH Analysis'!C1,Work_data!I:I,">="&DATE(2026,6,1),Work_data!I:I,"<="&DATE(2026,6,31)) -> 160
A9: Attrition % | B9: =B8/B6 -> 0.54263566 | C9: =C8/C6 -> 0.5311943 | D9: =D8/D6 -> 0.62622309
A10: Voluntary exits | B10: =COUNTIFS(Work_data!G:G,'WFH Analysis'!C1,Work_data!I:I,">="&DATE(2026,4,1),Work_data!I:I,"<="&DATE(2026,4,30),Work_data!K:K,"Voluntary") -> 76 | C10: =COUNTIFS(Work_data!G:G,'WFH Analysis'!C1,Work_data!I:I,">="&DATE(2026,5,1),Work_data!I:I,"<="&DATE(2026,5,31),Work_data!K:K,"Voluntary") -> 73 | D10: =COUNTIFS(Work_data!G:G,'WFH Analysis'!C1,Work_data!I:I,">="&DATE(2026,6,1),Work_data!I:I,"<="&DATE(2026,6,30),Work_data!K:K,"Voluntary") -> 77
A11: Involuntary exits | B11: =COUNTIFS(Work_data!G:G,'WFH Analysis'!C1,Work_data!I:I,">="&DATE(2026,4,1),Work_data!I:I,"<="&DATE(2026,4,30),Work_data!K:K,"Involuntary") -> 64 | C11: =COUNTIFS(Work_data!G:G,'WFH Analysis'!C1,Work_data!I:I,">="&DATE(2026,5,1),Work_data!I:I,"<="&DATE(2026,5,31),Work_data!K:K,"Involuntary") -> 76 | D11: =COUNTIFS(Work_data!G:G,'WFH Analysis'!C1,Work_data!I:I,">="&DATE(2026,6,1),Work_data!I:I,"<="&DATE(2026,6,30),Work_data!K:K,"Involuntary") -> 83
A12: Voluntary attrition % | B12: =B10/B6 -> 0.29457364 | C12: =C10/C6 -> 0.26024955 | D12: =D10/D6 -> 0.30136986
A13: Involuntary attrition % | B13: =B11/B6 -> 0.24806202 | C13: =C11/C6 -> 0.27094474 | D13: =D11/D6 -> 0.32485323

Sheet WFO Analysis
A1: Analysis by Work-Mode | C1: WFO
A3: Metric | B3: 46113 | C3: 46143 | D3: 46174
A4: Opening Headcount | B4: =COUNTIFS(Work_data!G:G,'WFO Analysis'!C1,Work_data!H:H,"<="&DATE(2026,4,1),Work_data!I:I,">="&DATE(2026,4,1))+COUNTIFS(Work_data!G:G,"WFO",Work_data!H:H,"<="&DATE(2026,4,1),Work_data!I:I,"") -> 114 | C4: =COUNTIFS(Work_data!G:G,'WFO Analysis'!C1,Work_data!H:H,"<="&DATE(2026,5,1),Work_data!I:I,">="&DATE(2026,5,1))+COUNTIFS(Work_data!G:G,"WFO",Work_data!H:H,"<="&DATE(2026,5,1),Work_data!I:I,"") -> 123 | D4: =COUNTIFS(Work_data!G:G,'WFO Analysis'!C1,Work_data!H:H,"<="&DATE(2026,6,1),Work_data!I:I,">="&DATE(2026,6,1))+COUNTIFS(Work_data!G:G,"WFO",Work_data!H:H,"<="&DATE(2026,6,1),Work_data!I:I,"") -> 96
A5: Closing Headcount | B5: =COUNTIFS(Work_data!G:G,'WFO Analysis'!C1,Work_data!H:H,"<="&DATE(2026,4,30),Work_data!I:I,">="&DATE(2026,4,30))+COUNTIFS(Work_data!G:G,"WFO",Work_data!H:H,"<="&DATE(2026,4,30),Work_data!I:I,"") -> 125 | C5: =COUNTIFS(Work_data!G:G,'WFO Analysis'!C1,Work_data!H:H,"<="&DATE(2026,5,31),Work_data!I:I,">="&DATE(2026,5,31))+COUNTIFS(Work_data!G:G,"WFO",Work_data!H:H,"<="&DATE(2026,5,31),Work_data!I:I,"") -> 98 | D5: =COUNTIFS(Work_data!G:G,'WFO Analysis'!C1,Work_data!H:H,"<="&DATE(2026,6,30),Work_data!I:I,">="&DATE(2026,6,30))+COUNTIFS(Work_data!G:G,"WFO",Work_data!H:H,"<="&DATE(2026,6,30),Work_data!I:I,"") -> 95
A6: Average Headcount | B6: =(B4+B5)/2 -> 119.5 | C6: =(C4+C5)/2 -> 110.5 | D6: =(D4+D5)/2 -> 95.5
A7: Joiners | B7: =COUNTIFS(Work_data!G:G,'WFO Analysis'!C1,Work_data!H:H,">="&DATE(2026,4,1),Work_data!H:H,"<="&DATE(2026,4,30)) -> 46 | C7: =COUNTIFS(Work_data!G:G,'WFO Analysis'!C1,Work_data!H:H,">="&DATE(2026,5,1),Work_data!H:H,"<="&DATE(2026,5,31)) -> 32 | D7: =COUNTIFS(Work_data!G:G,'WFO Analysis'!C1,Work_data!H:H,">="&DATE(2026,6,1),Work_data!H:H,"<="&DATE(2026,6,30)) -> 27
A8: Exits | B8: =COUNTIFS(Work_data!G:G,'WFO Analysis'!C1,Work_data!I:I,">="&DATE(2026,4,1),Work_data!I:I,"<="&DATE(2026,4,30)) -> 37 | C8: =COUNTIFS(Work_data!G:G,'WFO Analysis'!C1,Work_data!I:I,">="&DATE(2026,5,1),Work_data!I:I,"<="&DATE(2026,5,31)) -> 60 | D8: =COUNTIFS(Work_data!G:G,'WFO Analysis'!C1,Work_data!I:I,">="&DATE(2026,6,1),Work_data!I:I,"<="&DATE(2026,6,30)) -> 27
A9: Attrition % | B9: =B8/B6 -> 0.30962343 | C9: =C8/C6 -> 0.54298643 | D9: =D8/D6 -> 0.28272251
A10: Voluntary exits | B10: =COUNTIFS(Work_data!G:G,'WFO Analysis'!C1,Work_data!I:I,">="&DATE(2026,4,1),Work_data!I:I,"<="&DATE(2026,4,30),Work_data!K:K,"Voluntary") -> 25 | C10: =COUNTIFS(Work_data!G:G,'WFO Analysis'!C1,Work_data!I:I,">="&DATE(2026,5,1),Work_data!I:I,"<="&DATE(2026,5,31),Work_data!K:K,"Voluntary") -> 21 | D10: =COUNTIFS(Work_data!G:G,'WFO Analysis'!C1,Work_data!I:I,">="&DATE(2026,6,1),Work_data!I:I,"<="&DATE(2026,6,30),Work_data!K:K,"Voluntary") -> 18
A11: Involuntary exits | B11: =COUNTIFS(Work_data!G:G,'WFO Analysis'!C1,Work_data!I:I,">="&DATE(2026,4,1),Work_data!I:I,"<="&DATE(2026,4,30),Work_data!K:K,"Involuntary") -> 12 | C11: =COUNTIFS(Work_data!G:G,'WFO Analysis'!C1,Work_data!I:I,">="&DATE(2026,5,1),Work_data!I:I,"<="&DATE(2026,5,31),Work_data!K:K,"Involuntary") -> 39 | D11: =COUNTIFS(Work_data!G:G,'WFO Analysis'!C1,Work_data!I:I,">="&DATE(2026,6,1),Work_data!I:I,"<="&DATE(2026,6,30),Work_data!K:K,"Involuntary") -> 9
A12: Voluntary attrition % | B12: =B10/B6 -> 0.20920502 | C12: =C10/C6 -> 0.19004525 | D12: =D10/D6 -> 0.18848168
A13: Involuntary attrition % | B13: =B11/B6 -> 0.10041841 | C13: =C11/C6 -> 0.35294118 | D13: =D11/D6 -> 0.094240838

Sheet Top exit reason
A3: Row Labels | B3: Count of Employee ID | C3: Contribution %
A4: Personal Reasons | B4: 43 | C4: 0.07504363
A5: Relocation | B5: 44 | C5: 0.076788831
A6: Health Reasons | B6: 47 | C6: 0.082024433
A7: Better Opportunity | B7: 49 | C7: 0.085514834
A8: Family Reasons | B8: 50 | C8: 0.087260035
A9: Higher Studies | B9: 57 | C9: 0.09947644
A10: Policy Violation | B10: 58 | C10: 0.10122164
A11: Attendance / Discipline | B11: 70 | C11: 0.12216405
A12: Role Redundancy | B12: 72 | C12: 0.12565445
A13: Performance Related | B13: 83 | C13: 0.14485166
A14: Grand Total | B14: 573 | C14: 1

Sheet Tenure Bucket
A3: Count of Employee ID | B3: Column Labels
A4: Row Labels | B4: 0-90 | C4: 180-365 | D4: 90-180 | E4: above 1 year | F4: Grand Total
A5: Attendance / Discipline | B5: 22 | C5: 27 | D5: 5 | E5: 16 | F5: 70
A6: Better Opportunity | B6: 42 | C6: 4 | D6: 1 | E6: 2 | F6: 49
A7: Family Reasons | B7: 45 | C7: 1 | D7: 1 | E7: 3 | F7: 50
A8: Health Reasons | B8: 44 | C8: 2 | E8: 1 | F8: 47
A9: Higher Studies | B9: 55 | C9: 2 | F9: 57
A10: Performance Related | B10: 33 | C10: 25 | D10: 11 | E10: 14 | F10: 83
A11: Personal Reasons | B11: 39 | C11: 1 | D11: 2 | E11: 1 | F11: 43
A12: Policy Violation | B12: 26 | C12: 14 | D12: 8 | E12: 10 | F12: 58
A13: Relocation | B13: 41 | C13: 3 | F13: 44
A14: Role Redundancy | B14: 36 | C14: 23 | D14: 5 | E14: 8 | F14: 72
A15: Grand Total | B15: 383 | C15: 102 | D15: 33 | E15: 55 | F15: 573

Sheet WFH vs WHO
B2: 46113 | C2: 46143 | D2: 46174
A3: WFH | B3: 0.54263566 | C3: 0.5311943 | D3: 0.62622309
A4: WFO | B4: 0.30962343 | C4: 0.54298643 | D4: 0.28272251
